Traceback (most recent call last):
  File "/usr/share/miniconda3/envs/docbuild/lib/python3.10/site-packages/jupyter_cache/executors/utils.py", line 58, in single_nb_execution
    executenb(
  File "/usr/share/miniconda3/envs/docbuild/lib/python3.10/site-packages/nbclient/client.py", line 1314, in execute
    return NotebookClient(nb=nb, resources=resources, km=km, **kwargs).execute()
  File "/usr/share/miniconda3/envs/docbuild/lib/python3.10/site-packages/jupyter_core/utils/__init__.py", line 165, in wrapped
    return loop.run_until_complete(inner)
  File "/usr/share/miniconda3/envs/docbuild/lib/python3.10/asyncio/base_events.py", line 649, in run_until_complete
    return future.result()
  File "/usr/share/miniconda3/envs/docbuild/lib/python3.10/site-packages/nbclient/client.py", line 709, in async_execute
    await self.async_execute_cell(
  File "/usr/share/miniconda3/envs/docbuild/lib/python3.10/site-packages/nbclient/client.py", line 1062, in async_execute_cell
    await self._check_raise_for_error(cell, cell_index, exec_reply)
  File "/usr/share/miniconda3/envs/docbuild/lib/python3.10/site-packages/nbclient/client.py", line 918, in _check_raise_for_error
    raise CellExecutionError.from_cell_and_msg(cell, exec_reply_content)
nbclient.exceptions.CellExecutionError: An error occurred while executing the following cell:
------------------
state.settings.households_sample_size = 3500.8
state.settings.households_sample_size
------------------


[0;31m---------------------------------------------------------------------------[0m
[0;31mValidationError[0m                           Traceback (most recent call last)
Cell [0;32mIn[6], line 1[0m
[0;32m----> 1[0m [43mstate[49m[38;5;241;43m.[39;49m[43msettings[49m[38;5;241;43m.[39;49m[43mhouseholds_sample_size[49m [38;5;241m=[39m [38;5;241m3500.8[39m
[1;32m      2[0m state[38;5;241m.[39msettings[38;5;241m.[39mhouseholds_sample_size

File [0;32m/usr/share/miniconda3/envs/docbuild/lib/python3.10/site-packages/pydantic/main.py:792[0m, in [0;36mBaseModel.__setattr__[0;34m(self, name, value)[0m
[1;32m    790[0m     attr[38;5;241m.[39m[38;5;21m__set__[39m([38;5;28mself[39m, value)
[1;32m    791[0m [38;5;28;01melif[39;00m [38;5;28mself[39m[38;5;241m.[39mmodel_config[38;5;241m.[39mget([38;5;124m'[39m[38;5;124mvalidate_assignment[39m[38;5;124m'[39m, [38;5;28;01mNone[39;00m):
[0;32m--> 792[0m     [38;5;28;43mself[39;49m[38;5;241;43m.[39;49m[43m__pydantic_validator__[49m[38;5;241;43m.[39;49m[43mvalidate_assignment[49m[43m([49m[38;5;28;43mself[39;49m[43m,[49m[43m [49m[43mname[49m[43m,[49m[43m [49m[43mvalue[49m[43m)[49m
[1;32m    793[0m [38;5;28;01melif[39;00m [38;5;28mself[39m[38;5;241m.[39mmodel_config[38;5;241m.[39mget([38;5;124m'[39m[38;5;124mextra[39m[38;5;124m'[39m) [38;5;241m!=[39m [38;5;124m'[39m[38;5;124mallow[39m[38;5;124m'[39m [38;5;129;01mand[39;00m name [38;5;129;01mnot[39;00m [38;5;129;01min[39;00m [38;5;28mself[39m[38;5;241m.[39mmodel_fields:
[1;32m    794[0m     [38;5;66;03m# TODO - matching error[39;00m
[1;32m    795[0m     [38;5;28;01mraise[39;00m [38;5;167;01mValueError[39;00m([38;5;124mf[39m[38;5;124m'[39m[38;5;124m"[39m[38;5;132;01m{[39;00m[38;5;28mself[39m[38;5;241m.[39m[38;5;18m__class__[39m[38;5;241m.[39m[38;5;18m__name__[39m[38;5;132;01m}[39;00m[38;5;124m"[39m[38;5;124m object has no field [39m[38;5;124m"[39m[38;5;132;01m{[39;00mname[38;5;132;01m}[39;00m[38;5;124m"[39m[38;5;124m'[39m)

[0;31mValidationError[0m: 1 validation error for Settings
households_sample_size
  Input should be a valid integer, got a number with a fractional part [type=int_from_float, input_value=3500.8, input_type=float]
    For further information visit https://errors.pydantic.dev/2.6/v/int_from_float

